[2025-09-21T11:28:17.470+0000] {logging_mixin.py:151} INFO - Changing /opt/airflow/logs/dag_id=train_predict_to_db/run_id=scheduled__2025-09-21T11:22:00+00:00/task_id=validate_model_performance permission to 509
[2025-09-21T11:28:17.471+0000] {logging_mixin.py:151} INFO - Failed to change /opt/airflow/logs/dag_id=train_predict_to_db/run_id=scheduled__2025-09-21T11:22:00+00:00/task_id=validate_model_performance permission to 509: [Errno 1] Operation not permitted: '/opt/airflow/logs/dag_id=train_predict_to_db/run_id=scheduled__2025-09-21T11:22:00+00:00/task_id=validate_model_performance'
[2025-09-21T11:28:17.506+0000] {logging_mixin.py:151} INFO - Changing /opt/airflow/logs/dag_id=train_predict_to_db/run_id=scheduled__2025-09-21T11:22:00+00:00/task_id=validate_model_performance permission to 509
[2025-09-21T11:28:17.508+0000] {logging_mixin.py:151} INFO - Failed to change /opt/airflow/logs/dag_id=train_predict_to_db/run_id=scheduled__2025-09-21T11:22:00+00:00/task_id=validate_model_performance permission to 509: [Errno 1] Operation not permitted: '/opt/airflow/logs/dag_id=train_predict_to_db/run_id=scheduled__2025-09-21T11:22:00+00:00/task_id=validate_model_performance'
[2025-09-21T11:28:17.547+0000] {taskinstance.py:1159} INFO - Dependencies all met for dep_context=non-requeueable deps ti=<TaskInstance: train_predict_to_db.validate_model_performance scheduled__2025-09-21T11:22:00+00:00 [queued]>
[2025-09-21T11:28:17.557+0000] {taskinstance.py:1159} INFO - Dependencies all met for dep_context=requeueable deps ti=<TaskInstance: train_predict_to_db.validate_model_performance scheduled__2025-09-21T11:22:00+00:00 [queued]>
[2025-09-21T11:28:17.558+0000] {taskinstance.py:1361} INFO - Starting attempt 2 of 2
[2025-09-21T11:28:17.574+0000] {taskinstance.py:1382} INFO - Executing <Task(PythonOperator): validate_model_performance> on 2025-09-21 11:22:00+00:00
[2025-09-21T11:28:17.584+0000] {standard_task_runner.py:57} INFO - Started process 916 to run task
[2025-09-21T11:28:17.589+0000] {standard_task_runner.py:84} INFO - Running: ['airflow', 'tasks', 'run', 'train_predict_to_db', 'validate_model_performance', 'scheduled__2025-09-21T11:22:00+00:00', '--job-id', '74', '--raw', '--subdir', 'DAGS_FOLDER/train_predict_to_db_dag.py', '--cfg-path', '/tmp/tmp6yb91xue']
[2025-09-21T11:28:17.592+0000] {standard_task_runner.py:85} INFO - Job 74: Subtask validate_model_performance
[2025-09-21T11:28:17.657+0000] {logging_mixin.py:151} INFO - Changing /opt/airflow/logs/dag_id=train_predict_to_db/run_id=scheduled__2025-09-21T11:22:00+00:00/task_id=validate_model_performance permission to 509
[2025-09-21T11:28:17.657+0000] {logging_mixin.py:151} INFO - Failed to change /opt/airflow/logs/dag_id=train_predict_to_db/run_id=scheduled__2025-09-21T11:22:00+00:00/task_id=validate_model_performance permission to 509: [Errno 1] Operation not permitted: '/opt/airflow/logs/dag_id=train_predict_to_db/run_id=scheduled__2025-09-21T11:22:00+00:00/task_id=validate_model_performance'
[2025-09-21T11:28:17.659+0000] {task_command.py:416} INFO - Running <TaskInstance: train_predict_to_db.validate_model_performance scheduled__2025-09-21T11:22:00+00:00 [running]> on host 36da5371e73d
[2025-09-21T11:28:17.781+0000] {taskinstance.py:1662} INFO - Exporting env vars: AIRFLOW_CTX_DAG_OWNER='airflow' AIRFLOW_CTX_DAG_ID='train_predict_to_db' AIRFLOW_CTX_TASK_ID='validate_model_performance' AIRFLOW_CTX_EXECUTION_DATE='2025-09-21T11:22:00+00:00' AIRFLOW_CTX_TRY_NUMBER='2' AIRFLOW_CTX_DAG_RUN_ID='scheduled__2025-09-21T11:22:00+00:00'
[2025-09-21T11:28:17.942+0000] {taskinstance.py:1937} ERROR - Task failed with exception
Traceback (most recent call last):
  File "/home/airflow/.local/lib/python3.9/site-packages/airflow/operators/python.py", line 192, in execute
    return_value = self.execute_callable()
  File "/home/airflow/.local/lib/python3.9/site-packages/airflow/operators/python.py", line 209, in execute_callable
    return self.python_callable(*self.op_args, **self.op_kwargs)
  File "/opt/airflow/dags/train_predict_to_db_dag.py", line 60, in validate_model_performance
    raise Exception(f"Model R2 too low: {metrics['r2']}")
Exception: Model R2 too low: 0.006412268660229703
[2025-09-21T11:28:17.958+0000] {taskinstance.py:1400} INFO - Marking task as FAILED. dag_id=train_predict_to_db, task_id=validate_model_performance, execution_date=20250921T112200, start_date=20250921T112817, end_date=20250921T112817
[2025-09-21T11:28:17.974+0000] {standard_task_runner.py:104} ERROR - Failed to execute job 74 for task validate_model_performance (Model R2 too low: 0.006412268660229703; 916)
[2025-09-21T11:28:18.003+0000] {local_task_job_runner.py:228} INFO - Task exited with return code 1
[2025-09-21T11:28:18.023+0000] {taskinstance.py:2778} INFO - 0 downstream tasks scheduled from follow-on schedule check
