[2025-09-21T12:17:34.397+0000] {logging_mixin.py:151} INFO - Changing /opt/airflow/logs/dag_id=train_predict_to_db/run_id=scheduled__2025-09-21T12:12:00+00:00/task_id=validate_model_performance permission to 509
[2025-09-21T12:17:34.398+0000] {logging_mixin.py:151} INFO - Failed to change /opt/airflow/logs/dag_id=train_predict_to_db/run_id=scheduled__2025-09-21T12:12:00+00:00/task_id=validate_model_performance permission to 509: [Errno 1] Operation not permitted: '/opt/airflow/logs/dag_id=train_predict_to_db/run_id=scheduled__2025-09-21T12:12:00+00:00/task_id=validate_model_performance'
[2025-09-21T12:17:34.468+0000] {logging_mixin.py:151} INFO - Changing /opt/airflow/logs/dag_id=train_predict_to_db/run_id=scheduled__2025-09-21T12:12:00+00:00/task_id=validate_model_performance permission to 509
[2025-09-21T12:17:34.470+0000] {logging_mixin.py:151} INFO - Failed to change /opt/airflow/logs/dag_id=train_predict_to_db/run_id=scheduled__2025-09-21T12:12:00+00:00/task_id=validate_model_performance permission to 509: [Errno 1] Operation not permitted: '/opt/airflow/logs/dag_id=train_predict_to_db/run_id=scheduled__2025-09-21T12:12:00+00:00/task_id=validate_model_performance'
[2025-09-21T12:17:34.528+0000] {taskinstance.py:1159} INFO - Dependencies all met for dep_context=non-requeueable deps ti=<TaskInstance: train_predict_to_db.validate_model_performance scheduled__2025-09-21T12:12:00+00:00 [queued]>
[2025-09-21T12:17:34.544+0000] {taskinstance.py:1159} INFO - Dependencies all met for dep_context=requeueable deps ti=<TaskInstance: train_predict_to_db.validate_model_performance scheduled__2025-09-21T12:12:00+00:00 [queued]>
[2025-09-21T12:17:34.545+0000] {taskinstance.py:1361} INFO - Starting attempt 1 of 2
[2025-09-21T12:17:34.570+0000] {taskinstance.py:1382} INFO - Executing <Task(PythonOperator): validate_model_performance> on 2025-09-21 12:12:00+00:00
[2025-09-21T12:17:34.584+0000] {standard_task_runner.py:57} INFO - Started process 190 to run task
[2025-09-21T12:17:34.598+0000] {standard_task_runner.py:84} INFO - Running: ['airflow', 'tasks', 'run', 'train_predict_to_db', 'validate_model_performance', 'scheduled__2025-09-21T12:12:00+00:00', '--job-id', '191', '--raw', '--subdir', 'DAGS_FOLDER/train_predict_to_db_dag.py', '--cfg-path', '/tmp/tmpm20bsq6m']
[2025-09-21T12:17:34.614+0000] {standard_task_runner.py:85} INFO - Job 191: Subtask validate_model_performance
[2025-09-21T12:17:35.178+0000] {logging_mixin.py:151} INFO - Changing /opt/airflow/logs/dag_id=train_predict_to_db/run_id=scheduled__2025-09-21T12:12:00+00:00/task_id=validate_model_performance permission to 509
[2025-09-21T12:17:35.179+0000] {logging_mixin.py:151} INFO - Failed to change /opt/airflow/logs/dag_id=train_predict_to_db/run_id=scheduled__2025-09-21T12:12:00+00:00/task_id=validate_model_performance permission to 509: [Errno 1] Operation not permitted: '/opt/airflow/logs/dag_id=train_predict_to_db/run_id=scheduled__2025-09-21T12:12:00+00:00/task_id=validate_model_performance'
[2025-09-21T12:17:35.183+0000] {task_command.py:416} INFO - Running <TaskInstance: train_predict_to_db.validate_model_performance scheduled__2025-09-21T12:12:00+00:00 [running]> on host 1bfed80107dd
[2025-09-21T12:17:35.445+0000] {taskinstance.py:1662} INFO - Exporting env vars: AIRFLOW_CTX_DAG_OWNER='airflow' AIRFLOW_CTX_DAG_ID='train_predict_to_db' AIRFLOW_CTX_TASK_ID='validate_model_performance' AIRFLOW_CTX_EXECUTION_DATE='2025-09-21T12:12:00+00:00' AIRFLOW_CTX_TRY_NUMBER='1' AIRFLOW_CTX_DAG_RUN_ID='scheduled__2025-09-21T12:12:00+00:00'
[2025-09-21T12:17:36.444+0000] {taskinstance.py:1937} ERROR - Task failed with exception
Traceback (most recent call last):
  File "/home/airflow/.local/lib/python3.9/site-packages/requests/models.py", line 971, in json
    return complexjson.loads(self.text, **kwargs)
  File "/usr/local/lib/python3.9/json/__init__.py", line 346, in loads
    return _default_decoder.decode(s)
  File "/usr/local/lib/python3.9/json/decoder.py", line 337, in decode
    obj, end = self.raw_decode(s, idx=_w(s, 0).end())
  File "/usr/local/lib/python3.9/json/decoder.py", line 355, in raw_decode
    raise JSONDecodeError("Expecting value", s, err.value) from None
json.decoder.JSONDecodeError: Expecting value: line 1 column 1 (char 0)

During handling of the above exception, another exception occurred:

Traceback (most recent call last):
  File "/home/airflow/.local/lib/python3.9/site-packages/airflow/operators/python.py", line 192, in execute
    return_value = self.execute_callable()
  File "/home/airflow/.local/lib/python3.9/site-packages/airflow/operators/python.py", line 209, in execute_callable
    return self.python_callable(*self.op_args, **self.op_kwargs)
  File "/opt/airflow/dags/train_predict_to_db_dag.py", line 58, in validate_model_performance
    metrics = response.json()['metrics']
  File "/home/airflow/.local/lib/python3.9/site-packages/requests/models.py", line 975, in json
    raise RequestsJSONDecodeError(e.msg, e.doc, e.pos)
requests.exceptions.JSONDecodeError: Expecting value: line 1 column 1 (char 0)
[2025-09-21T12:17:36.597+0000] {taskinstance.py:1400} INFO - Marking task as UP_FOR_RETRY. dag_id=train_predict_to_db, task_id=validate_model_performance, execution_date=20250921T121200, start_date=20250921T121734, end_date=20250921T121736
[2025-09-21T12:17:37.113+0000] {standard_task_runner.py:104} ERROR - Failed to execute job 191 for task validate_model_performance (Expecting value: line 1 column 1 (char 0); 190)
[2025-09-21T12:17:37.148+0000] {local_task_job_runner.py:228} INFO - Task exited with return code 1
[2025-09-21T12:17:37.183+0000] {taskinstance.py:2778} INFO - 0 downstream tasks scheduled from follow-on schedule check
