[2025-09-21T11:14:14.573+0000] {logging_mixin.py:151} INFO - Changing /opt/airflow/logs/dag_id=train_predict_to_db/run_id=scheduled__2025-09-21T11:13:00+00:00/task_id=validate_model_performance permission to 509
[2025-09-21T11:14:14.574+0000] {logging_mixin.py:151} INFO - Failed to change /opt/airflow/logs/dag_id=train_predict_to_db/run_id=scheduled__2025-09-21T11:13:00+00:00/task_id=validate_model_performance permission to 509: [Errno 1] Operation not permitted: '/opt/airflow/logs/dag_id=train_predict_to_db/run_id=scheduled__2025-09-21T11:13:00+00:00/task_id=validate_model_performance'
[2025-09-21T11:14:14.629+0000] {logging_mixin.py:151} INFO - Changing /opt/airflow/logs/dag_id=train_predict_to_db/run_id=scheduled__2025-09-21T11:13:00+00:00/task_id=validate_model_performance permission to 509
[2025-09-21T11:14:14.632+0000] {logging_mixin.py:151} INFO - Failed to change /opt/airflow/logs/dag_id=train_predict_to_db/run_id=scheduled__2025-09-21T11:13:00+00:00/task_id=validate_model_performance permission to 509: [Errno 1] Operation not permitted: '/opt/airflow/logs/dag_id=train_predict_to_db/run_id=scheduled__2025-09-21T11:13:00+00:00/task_id=validate_model_performance'
[2025-09-21T11:14:14.714+0000] {taskinstance.py:1159} INFO - Dependencies all met for dep_context=non-requeueable deps ti=<TaskInstance: train_predict_to_db.validate_model_performance scheduled__2025-09-21T11:13:00+00:00 [queued]>
[2025-09-21T11:14:14.733+0000] {taskinstance.py:1159} INFO - Dependencies all met for dep_context=requeueable deps ti=<TaskInstance: train_predict_to_db.validate_model_performance scheduled__2025-09-21T11:13:00+00:00 [queued]>
[2025-09-21T11:14:14.734+0000] {taskinstance.py:1361} INFO - Starting attempt 1 of 2
[2025-09-21T11:14:14.765+0000] {taskinstance.py:1382} INFO - Executing <Task(PythonOperator): validate_model_performance> on 2025-09-21 11:13:00+00:00
[2025-09-21T11:14:14.788+0000] {standard_task_runner.py:57} INFO - Started process 484 to run task
[2025-09-21T11:14:14.798+0000] {standard_task_runner.py:84} INFO - Running: ['airflow', 'tasks', 'run', 'train_predict_to_db', 'validate_model_performance', 'scheduled__2025-09-21T11:13:00+00:00', '--job-id', '29', '--raw', '--subdir', 'DAGS_FOLDER/train_predict_to_db_dag.py', '--cfg-path', '/tmp/tmpjgmv8jx1']
[2025-09-21T11:14:14.806+0000] {standard_task_runner.py:85} INFO - Job 29: Subtask validate_model_performance
[2025-09-21T11:14:14.923+0000] {logging_mixin.py:151} INFO - Changing /opt/airflow/logs/dag_id=train_predict_to_db/run_id=scheduled__2025-09-21T11:13:00+00:00/task_id=validate_model_performance permission to 509
[2025-09-21T11:14:14.924+0000] {logging_mixin.py:151} INFO - Failed to change /opt/airflow/logs/dag_id=train_predict_to_db/run_id=scheduled__2025-09-21T11:13:00+00:00/task_id=validate_model_performance permission to 509: [Errno 1] Operation not permitted: '/opt/airflow/logs/dag_id=train_predict_to_db/run_id=scheduled__2025-09-21T11:13:00+00:00/task_id=validate_model_performance'
[2025-09-21T11:14:14.929+0000] {task_command.py:416} INFO - Running <TaskInstance: train_predict_to_db.validate_model_performance scheduled__2025-09-21T11:13:00+00:00 [running]> on host 36da5371e73d
[2025-09-21T11:14:15.143+0000] {taskinstance.py:1662} INFO - Exporting env vars: AIRFLOW_CTX_DAG_OWNER='airflow' AIRFLOW_CTX_DAG_ID='train_predict_to_db' AIRFLOW_CTX_TASK_ID='validate_model_performance' AIRFLOW_CTX_EXECUTION_DATE='2025-09-21T11:13:00+00:00' AIRFLOW_CTX_TRY_NUMBER='1' AIRFLOW_CTX_DAG_RUN_ID='scheduled__2025-09-21T11:13:00+00:00'
[2025-09-21T11:14:15.224+0000] {taskinstance.py:1937} ERROR - Task failed with exception
Traceback (most recent call last):
  File "/home/airflow/.local/lib/python3.9/site-packages/airflow/operators/python.py", line 192, in execute
    return_value = self.execute_callable()
  File "/home/airflow/.local/lib/python3.9/site-packages/airflow/operators/python.py", line 209, in execute_callable
    return self.python_callable(*self.op_args, **self.op_kwargs)
  File "/opt/airflow/dags/train_predict_to_db_dag.py", line 60, in validate_model_performance
    raise Exception(f"Model R2 too low: {metrics['r2']}")
Exception: Model R2 too low: 0.6457114319526547
[2025-09-21T11:14:15.254+0000] {taskinstance.py:1400} INFO - Marking task as UP_FOR_RETRY. dag_id=train_predict_to_db, task_id=validate_model_performance, execution_date=20250921T111300, start_date=20250921T111414, end_date=20250921T111415
[2025-09-21T11:14:15.283+0000] {standard_task_runner.py:104} ERROR - Failed to execute job 29 for task validate_model_performance (Model R2 too low: 0.6457114319526547; 484)
[2025-09-21T11:14:15.331+0000] {local_task_job_runner.py:228} INFO - Task exited with return code 1
[2025-09-21T11:14:15.370+0000] {taskinstance.py:2778} INFO - 0 downstream tasks scheduled from follow-on schedule check
